<mujoco>
    <option timestep="0.01" solver="Newton" iterations="6" ls_iterations="8"/>
    <custom>
        <numeric data="10" name="max_geom_pairs"/>
    </custom>
    <default>
        <geom condim="6" density="1"/>
        <joint damping=".001"/>
        <motor ctrlrange="-1 1" ctrllimited="true" forcerange="-.05 .05" forcelimited="true"/>
        <velocity ctrlrange="-1 1" ctrllimited="true" forcerange="-.05 .05" forcelimited="true"/>
        <site size="0.032" type="sphere"/>
    </default>
    <worldbody>
        <!-- Visualisation -->
        <light cutoff="100" diffuse="1 1 1" dir="0 0 -1" directional="true"exponent="1" pos="0 0 0.5" specular="0 0 0" castshadow="false"/>
        <camera name="fixednear" pos="0 -2 2" zaxis="0 -1 1"/>
        <camera name="fixedfar" pos="0 -5 5" zaxis="0 -1 1"/>
        <!-- Floor with material from asset section -->
        <geom name="floor" type="plane" condim="6" size="5 5 0.1" rgba="1 1 1 1" material="MatPlane"/>
        <body name="robot" pos="0 0 .1">
            <!-- <camera name="vision" pos="0 0 .15" xyaxes="0 -1 0 .4 0 1" fovy="90"/> -->
            <joint type="slide" axis="1 0 0" name="x" damping="0.01"/>
            <joint type="slide" axis="0 1 0" name="y" damping="0.01"/>
            <joint type="hinge" axis="0 0 1" name="z" damping="0.005"/>
            <geom name="robot" type="sphere" size=".1" friction="1 0.01 0.01" rgba="1 0 0 1"/>
            <geom name="pointarrow" pos="0.1 0 0" size="0.05 0.05 0.05" rgba="1 0 0 1" type="box"/>
            <site name="robot" rgba="1 0 0 .1"/>
        </body>
    </worldbody>
    <sensor>
        <!-- Used for observation -->
        <accelerometer site="robot" name="accelerometer"/>
        <velocimeter site="robot" name="velocimeter"/>
        <gyro site="robot" name="gyro"/>
        <magnetometer site="robot" name="magnetometer"/>
        <!-- Used for intrinsic constraints -->
        <subtreecom body="robot" name="subtreecom"/>
        <subtreelinvel body="robot" name="subtreelinvel"/>
        <subtreeangmom body="robot" name="subtreeangmom"/>
    </sensor>
    <actuator>
        <motor gear="0.3 0 0 0 0 0" site="robot" name="x"/>
        <velocity gear="0.3" joint="z" name="z"/>
    </actuator>
    <asset>
        <texture type="skybox" builtin="gradient" rgb1="0.527 0.582 0.906" rgb2="0.1 0.1 0.35"
            width="800" height="800" markrgb="1 1 1" mark="random" random="0.001"/>
        <texture name="texplane" builtin="checker" height="100" width="100"
            rgb1="0.7 0.7 0.7" rgb2="0.8 0.8 0.8" type="2d"/>
        <material name="MatPlane" reflectance="0.1" shininess="0.1" specular="0.1"
            texrepeat="10 10" texture="texplane"/>
    </asset>
</mujoco>